Workbook

Sheet shortage_onc
A1: Drug | B1: Company | C1: Presentation | D1: Availability | E1: Reason | F1: Initial Posting Date | G1: Date of Update | H1: Therapeutic Category
A2: Azacitidine Injection | B2: Accord Healthcare Inc. | C2: Azacitidine, Injection, 100 mg (NDC 16729-306-10) | D2: Available | E2: Not stated | F2: 44186 | G2: 46312 | H2: Oncology
A3: Azacitidine Injection | B3: Armas Pharmaceuticals Inc | C3: Azacitidine, Injection, 100 mg (NDC 72485-201-01) | D3: Limited Availability | E3: Other | F3: 44183 | G3: 46181 | H3: Oncology
A4: Azacitidine Injection | B4: Bristol Myers Squibb Co. | C4: Vidaza, Injection, 100 mg (NDC 59572-102-01) | D4: Available | E4: Not stated | F4: 44183 | G4: 46310 | H4: Oncology
A5: Azacitidine Injection | B5: Dr. Reddy's Laboratories, Inc. | C5: Azacitidine, Injection, 100 mg (NDC 43598-305-62) | D5: Available | E5: Not stated | F5: 44183 | G5: 46315 | H5: Oncology
A6: Azacitidine Injection | B6: Eugia US LLC | C6: Azacitidine, Injection, 100 mg/4 mL (NDC 55150-393-01) | D6: Unavailable | E6: Demand increase for the drug | F6: 44187 | G6: 46314 | H6: Oncology
A7: Azacitidine Injection | B7: Fresenius Kabi USA, LLC | C7: Azacitidine, Injection, 100 mg/30 mL (NDC 63323-771-39) | D7: Unavailable | E7: Discontinuation of the manufacture of the drug | F7: 44183 | G7: 46310 | H7: Oncology
A8: Azacitidine Injection | B8: Hikma Pharmaceuticals USA, Inc. | C8: Azacitidine, Injection, 100 mg/ Vial (NDC 0143-9606-01) | D8: Unavailable | E8: Demand increase for the drug | F8: 44183 | G8: 46309 | H8: Oncology
A9: Azacitidine Injection | B9: Meitheal Pharmaceuticals, Inc. | C9: Azacitidine, Injection, 100 mg/30 mL (NDC 71288-115-30) | D9: Available | E9: Not stated | F9: 44183 | G9: 46261 | H9: Oncology
A10: Azacitidine Injection | B10: Teva Pharmaceuticals USA, Inc. | C10: Azacitidine, Injection, 100 mg (NDC 68001-313-56) | D10: Unavailable | E10: Other | F10: 44187 | G10: 46310 | H10: Oncology
A11: Carboplatin Injection | B11: Accord Healthcare Inc. | C11: Carboplatin, Injection, 10 mg/1 mL (NDC 16729-295-12) | D11: Unavailable | E11: Demand increase for the drug | F11: 45044 | G11: 46312 | H11: Oncology
A12: Carboplatin Injection | B12: Accord Healthcare Inc. | C12: Carboplatin, Injection, 10 mg/1 mL (NDC 16729-295-31) | D12: Unavailable | E12: Demand increase for the drug | F12: 45044 | G12: 46312 | H12: Oncology
A13: Carboplatin Injection | B13: Accord Healthcare Inc. | C13: Carboplatin, Injection, 10 mg/1 mL (NDC 16729-295-33) | D13: Unavailable | E13: Demand increase for the drug | F13: 45044 | G13: 46312 | H13: Oncology
... A84: Streptozocin Powder, For Solution | B84: Teva Pharmaceuticals USA, Inc. | C84: Zanosar, Powder, For Solution, 100 mg/1 mL (NDC 0703-4636-01) | D84: Unavailable | E84: Other | F84: 44754 | G84: 46310 | H84: Oncology

Sheet Data
A1: Drug | B1: Shortage records | C1: Unavailable records | D1: % unavailable | E1: Companies in shortage | F1: First posted | G1: Years in Shortage | H1: NDC products | I1: Marketing companies | J1: Generic approvals (ANDA) | K1: Top company share | L1: In scope
A2: {=_xlfn._xlws.SORT(_xlfn.UNIQUE(shortage_onc!A2:A84))} -> Azacitidine Injection | B2: =COUNTIFS(shortage_onc!$A$2:$A$84,A2) -> 9 | C2: =COUNTIFS(shortage_onc!$A$2:$A$84,A2,shortage_onc!$D$2:$D$84,"Unavailable") -> 4 | D2: =C2/B2 -> 0.44444444 | E2: {=ROWS(_xlfn.UNIQUE(_xlfn._xlws.FILTER(shortage_onc!$B$2:$B$84,shortage_onc!$A$2:$A$84=A2)))} -> 9 | F2: =_xlfn.MINIFS(shortage_onc!$F$2:$F$84,shortage_onc!$A$2:$A$84,A2) -> 44183 | G2: =ROUND((DATE(2026,10,29)-F2)/365.25,2) -> 5.86 | H2: {=ROWS(_xlfn.UNIQUE(_xlfn._xlws.FILTER(ndc_onc!$B$2:$B$217,ndc_onc!$A$2:$A$217=A2)))} -> 25 | I2: {=ROWS(_xlfn.UNIQUE(_xlfn._xlws.FILTER(ndc_onc!$H$2:$H$217,ndc_onc!$A$2:$A$217=A2)))} -> 21 | J2: {=IFERROR(ROWS(_xlfn.UNIQUE(_xlfn._xlws.FILTER(ndc_onc!$G$2:$G$217,(ndc_onc!$A$2:$A$217=A2)*(ndc_onc!$F$2:$F$217="ANDA")))),0)} -> 12 | K2: {=MAX(COUNTIFS(shortage_onc!$A$2:$A$84,A2,shortage_onc!$B$2:$B$84,_xlfn.UNIQUE(_xlfn._xlws.FILTER(shortage_onc!$B$2:$B$84,shortage_onc!$A$2:$A$84=A2))))/B2} -> 0.11111111 | L2: =IF(ISNUMBER(SEARCH("Flurazepam",A2)),"No","Yes") -> Yes
A3: Carboplatin Injection | B3: =COUNTIFS(shortage_onc!$A$2:$A$84,A3) -> 29 | C3: =COUNTIFS(shortage_onc!$A$2:$A$84,A3,shortage_onc!$D$2:$D$84,"Unavailable") -> 12 | D3: =C3/B3 -> 0.4137931 | E3: {=ROWS(_xlfn.UNIQUE(_xlfn._xlws.FILTER(shortage_onc!$B$2:$B$84,shortage_onc!$A$2:$A$84=A3)))} -> 8 | F3: =_xlfn.MINIFS(shortage_onc!$F$2:$F$84,shortage_onc!$A$2:$A$84,A3) -> 45044 | G3: =ROUND((DATE(2026,10,29)-F3)/365.25,2) -> 3.5 | H3: {=ROWS(_xlfn.UNIQUE(_xlfn._xlws.FILTER(ndc_onc!$B$2:$B$217,ndc_onc!$A$2:$A$217=A3)))} -> 34 | I3: {=ROWS(_xlfn.UNIQUE(_xlfn._xlws.FILTER(ndc_onc!$H$2:$H$217,ndc_onc!$A$2:$A$217=A3)))} -> 11 | J3: {=IFERROR(ROWS(_xlfn.UNIQUE(_xlfn._xlws.FILTER(ndc_onc!$G$2:$G$217,(ndc_onc!$A$2:$A$217=A3)*(ndc_onc!$F$2:$F$217="ANDA")))),0)} -> 8 | K3: {=MAX(COUNTIFS(shortage_onc!$A$2:$A$84,A3,shortage_onc!$B$2:$B$84,_xlfn.UNIQUE(_xlfn._xlws.FILTER(shortage_onc!$B$2:$B$84,shortage_onc!$A$2:$A$84=A3))))/B3} -> 0.27586207 | L3: =IF(ISNUMBER(SEARCH("Flurazepam",A3)),"No","Yes") -> Yes
A4: Dexamethasone Sodium Phosphate Injection | B4: =COUNTIFS(shortage_onc!$A$2:$A$84,A4) -> 19 | C4: =COUNTIFS(shortage_onc!$A$2:$A$84,A4,shortage_onc!$D$2:$D$84,"Unavailable") -> 4 | D4: =C4/B4 -> 0.21052632 | E4: {=ROWS(_xlfn.UNIQUE(_xlfn._xlws.FILTER(shortage_onc!$B$2:$B$84,shortage_onc!$A$2:$A$84=A4)))} -> 5 | F4: =_xlfn.MINIFS(shortage_onc!$F$2:$F$84,shortage_onc!$A$2:$A$84,A4) -> 43504 | G4: =ROUND((DATE(2026,10,29)-F4)/365.25,2) -> 7.72 | H4: {=ROWS(_xlfn.UNIQUE(_xlfn._xlws.FILTER(ndc_onc!$B$2:$B$217,ndc_onc!$A$2:$A$217=A4)))} -> 95 | I4: {=ROWS(_xlfn.UNIQUE(_xlfn._xlws.FILTER(ndc_onc!$H$2:$H$217,ndc_onc!$A$2:$A$217=A4)))} -> 25 | J4: {=IFERROR(ROWS(_xlfn.UNIQUE(_xlfn._xlws.FILTER(ndc_onc!$G$2:$G$217,(ndc_onc!$A$2:$A$217=A4)*(ndc_onc!$F$2:$F$217="ANDA")))),0)} -> 19 | K4: {=MAX(COUNTIFS(shortage_onc!$A$2:$A$84,A4,shortage_onc!$B$2:$B$84,_xlfn.UNIQUE(_xlfn._xlws.FILTER(shortage_onc!$B$2:$B$84,shortage_onc!$A$2:$A$84=A4))))/B4} -> 0.47368421 | L4: =IF(ISNUMBER(SEARCH("Flurazepam",A4)),"No","Yes") -> Yes
A5: Flurazepam Hydrochloride Capsule | B5: =COUNTIFS(shortage_onc!$A$2:$A$84,A5) -> 1 | C5: =COUNTIFS(shortage_onc!$A$2:$A$84,A5,shortage_onc!$D$2:$D$84,"Unavailable") -> 0 | D5: =C5/B5 -> 0 | E5: {=ROWS(_xlfn.UNIQUE(_xlfn._xlws.FILTER(shortage_onc!$B$2:$B$84,shortage_onc!$A$2:$A$84=A5)))} -> 1 | F5: =_xlfn.MINIFS(shortage_onc!$F$2:$F$84,shortage_onc!$A$2:$A$84,A5) -> 44776 | G5: =ROUND((DATE(2026,10,29)-F5)/365.25,2) -> 4.24 | H5: {=ROWS(_xlfn.UNIQUE(_xlfn._xlws.FILTER(ndc_onc!$B$2:$B$217,ndc_onc!$A$2:$A$217=A5)))} -> 2 | I5: {=ROWS(_xlfn.UNIQUE(_xlfn._xlws.FILTER(ndc_onc!$H$2:$H$217,ndc_onc!$A$2:$A$217=A5)))} -> 1 | J5: {=IFERROR(ROWS(_xlfn.UNIQUE(_xlfn._xlws.FILTER(ndc_onc!$G$2:$G$217,(ndc_onc!$A$2:$A$217=A5)*(ndc_onc!$F$2:$F$217="ANDA")))),0)} -> 2 | K5: {=MAX(COUNTIFS(shortage_onc!$A$2:$A$84,A5,shortage_onc!$B$2:$B$84,_xlfn.UNIQUE(_xlfn._xlws.FILTER(shortage_onc!$B$2:$B$84,shortage_onc!$A$2:$A$84=A5))))/B5} -> 1 | L5: =IF(ISNUMBER(SEARCH("Flurazepam",A5)),"No","Yes") -> No
A6: Ifosfamide Injection | B6: =COUNTIFS(shortage_onc!$A$2:$A$84,A6) -> 8 | C6: =COUNTIFS(shortage_onc!$A$2:$A$84,A6,shortage_onc!$D$2:$D$84,"Unavailable") -> 3 | D6: =C6/B6 -> 0.375 | E6: {=ROWS(_xlfn.UNIQUE(_xlfn._xlws.FILTER(shortage_onc!$B$2:$B$84,shortage_onc!$A$2:$A$84=A6)))} -> 4 | F6: =_xlfn.MINIFS(shortage_onc!$F$2:$F$84,shortage_onc!$A$2:$A$84,A6) -> 46185 | G6: =ROUND((DATE(2026,10,29)-F6)/365.25,2) -> 0.38 | H6: {=ROWS(_xlfn.UNIQUE(_xlfn._xlws.FILTER(ndc_onc!$B$2:$B$217,ndc_onc!$A$2:$A$217=A6)))} -> 12 | I6: {=ROWS(_xlfn.UNIQUE(_xlfn._xlws.FILTER(ndc_onc!$H$2:$H$217,ndc_onc!$A$2:$A$217=A6)))} -> 6 | J6: {=IFERROR(ROWS(_xlfn.UNIQUE(_xlfn._xlws.FILTER(ndc_onc!$G$2:$G$217,(ndc_onc!$A$2:$A$217=A6)*(ndc_onc!$F$2:$F$217="ANDA")))),0)} -> 3 | K6: {=MAX(COUNTIFS(shortage_onc!$A$2:$A$84,A6,shortage_onc!$B$2:$B$84,_xlfn.UNIQUE(_xlfn._xlws.FILTER(shortage_onc!$B$2:$B$84,shortage_onc!$A$2:$A$84=A6))))/B6} -> 0.5 | L6: =IF(ISNUMBER(SEARCH("Flurazepam",A6)),"No","Yes") -> Yes
A7: Methotrexate Sodium Injection | B7: =COUNTIFS(shortage_onc!$A$2:$A$84,A7) -> 14 | C7: =COUNTIFS(shortage_onc!$A$2:$A$84,A7,shortage_onc!$D$2:$D$84,"Unavailable") -> 4 | D7: =C7/B7 -> 0.28571429 | E7: {=ROWS(_xlfn.UNIQUE(_xlfn._xlws.FILTER(shortage_onc!$B$2:$B$84,shortage_onc!$A$2:$A$84=A7)))} -> 5 | F7: =_xlfn.MINIFS(shortage_onc!$F$2:$F$84,shortage_onc!$A$2:$A$84,A7) -> 44998 | G7: =ROUND((DATE(2026,10,29)-F7)/365.25,2) -> 3.63 | H7: {=ROWS(_xlfn.UNIQUE(_xlfn._xlws.FILTER(ndc_onc!$B$2:$B$217,ndc_onc!$A$2:$A$217=A7)))} -> 36 | I7: {=ROWS(_xlfn.UNIQUE(_xlfn._xlws.FILTER(ndc_onc!$H$2:$H$217,ndc_onc!$A$2:$A$217=A7)))} -> 10 | J7: {=IFERROR(ROWS(_xlfn.UNIQUE(_xlfn._xlws.FILTER(ndc_onc!$G$2:$G$217,(ndc_onc!$A$2:$A$217=A7)*(ndc_onc!$F$2:$F$217="ANDA")))),0)} -> 7 | K7: {=MAX(COUNTIFS(shortage_onc!$A$2:$A$84,A7,shortage_onc!$B$2:$B$84,_xlfn.UNIQUE(_xlfn._xlws.FILTER(shortage_onc!$B$2:$B$84,shortage_onc!$A$2:$A$84=A7))))/B7} -> 0.35714286 | L7: =IF(ISNUMBER(SEARCH("Flurazepam",A7)),"No","Yes") -> Yes
A8: Pentostatin Injection | B8: =COUNTIFS(shortage_onc!$A$2:$A$84,A8) -> 1 | C8: =COUNTIFS(shortage_onc!$A$2:$A$84,A8,shortage_onc!$D$2:$D$84,"Unavailable") -> 1 | D8: =C8/B8 -> 1 | E8: {=ROWS(_xlfn.UNIQUE(_xlfn._xlws.FILTER(shortage_onc!$B$2:$B$84,shortage_onc!$A$2:$A$84=A8)))} -> 1 | F8: =_xlfn.MINIFS(shortage_onc!$F$2:$F$84,shortage_onc!$A$2:$A$84,A8) -> 46261 | G8: =ROUND((DATE(2026,10,29)-F8)/365.25,2) -> 0.17 | H8: {=ROWS(_xlfn.UNIQUE(_xlfn._xlws.FILTER(ndc_onc!$B$2:$B$217,ndc_onc!$A$2:$A$217=A8)))} -> 1 | I8: {=ROWS(_xlfn.UNIQUE(_xlfn._xlws.FILTER(ndc_onc!$H$2:$H$217,ndc_onc!$A$2:$A$217=A8)))} -> 1 | J8: {=IFERROR(ROWS(_xlfn.UNIQUE(_xlfn._xlws.FILTER(ndc_onc!$G$2:$G$217,(ndc_onc!$A$2:$A$217=A8)*(ndc_onc!$F$2:$F$217="ANDA")))),0)} -> 0 | K8: {=MAX(COUNTIFS(shortage_onc!$A$2:$A$84,A8,shortage_onc!$B$2:$B$84,_xlfn.UNIQUE(_xlfn._xlws.FILTER(shortage_onc!$B$2:$B$84,shortage_onc!$A$2:$A$84=A8))))/B8} -> 1 | L8: =IF(ISNUMBER(SEARCH("Flurazepam",A8)),"No","Yes") -> Yes
A9: Streptozocin Powder, For Solution | B9: =COUNTIFS(shortage_onc!$A$2:$A$84,A9) -> 2 | C9: =COUNTIFS(shortage_onc!$A$2:$A$84,A9,shortage_onc!$D$2:$D$84,"Unavailable") -> 1 | D9: =C9/B9 -> 0.5 | E9: {=ROWS(_xlfn.UNIQUE(_xlfn._xlws.FILTER(shortage_onc!$B$2:$B$84,shortage_onc!$A$2:$A$84=A9)))} -> 2 | F9: =_xlfn.MINIFS(shortage_onc!$F$2:$F$84,shortage_onc!$A$2:$A$84,A9) -> 44754 | G9: =ROUND((DATE(2026,10,29)-F9)/365.25,2) -> 4.3 | H9: {=ROWS(_xlfn.UNIQUE(_xlfn._xlws.FILTER(ndc_onc!$B$2:$B$217,ndc_onc!$A$2:$A$217=A9)))} -> 1 | I9: {=ROWS(_xlfn.UNIQUE(_xlfn._xlws.FILTER(ndc_onc!$H$2:$H$217,ndc_onc!$A$2:$A$217=A9)))} -> 1 | J9: {=IFERROR(ROWS(_xlfn.UNIQUE(_xlfn._xlws.FILTER(ndc_onc!$G$2:$G$217,(ndc_onc!$A$2:$A$217=A9)*(ndc_onc!$F$2:$F$217="ANDA")))),0)} -> 0 | K9: {=MAX(COUNTIFS(shortage_onc!$A$2:$A$84,A9,shortage_onc!$B$2:$B$84,_xlfn.UNIQUE(_xlfn._xlws.FILTER(shortage_onc!$B$2:$B$84,shortage_onc!$A$2:$A$84=A9))))/B9} -> 0.5 | L9: =IF(ISNUMBER(SEARCH("Flurazepam",A9)),"No","Yes") -> Yes

Sheet ndc_onc
A1: Drug | B1: PRODUCTNDC | C1: PROPRIETARYNAME | D1: NONPROPRIETARYNAME | E1: DOSAGEFORMNAME | F1: MARKETINGCATEGORYNAME | G1: APPLICATIONNUMBER | H1: LABELERNAME | I1: SUBSTANCENAME | J1: ACTIVE_NUMERATOR_STRENGTH | K1: ACTIVE_INGRED_UNIT | L1: STARTMARKETINGDATE
A2: Azacitidine Injection | B2: 16729-306 | C2: Azacitidine | D2: Azacitidine | E2: INJECTION, POWDER, LYOPHILIZED, FOR SOLUTION | F2: ANDA | G2: ANDA207475 | H2: Accord Healthcare Inc. | I2: AZACITIDINE | J2: 100 | K2: mg/1 | L2: 20190109
A3: Azacitidine Injection | B3: 70121-1237 | C3: AZACITIDINE | D3: AZACITIDINE | E3: INJECTION, POWDER, LYOPHILIZED, FOR SOLUTION | F3: ANDA | G3: ANDA211549 | H3: Amneal Pharmaceuticals LLC | I3: AZACITIDINE | J3: 100 | K3: mg/1 | L3: 20220209
A4: Azacitidine Injection | B4: 60505-6271 | C4: Azacitidine | D4: azacitidine | E4: INJECTION, POWDER, LYOPHILIZED, FOR SOLUTION | F4: ANDA | G4: ANDA215905 | H4: Apotex Corp | I4: AZACITIDINE | J4: 100 | K4: mg/1 | L4: 20240123
A5: Azacitidine Injection | B5: 72485-201 | C5: AZACITIDINE | D5: azacitidine | E5: INJECTION, POWDER, LYOPHILIZED, FOR SOLUTION | F5: ANDA | G5: ANDA207518 | H5: Armas Pharmaceuticals Inc. | I5: AZACITIDINE | J5: 100 | K5: mg/1 | L5: 20180910
A6: Azacitidine Injection | B6: 68001-313 | C6: Azacitidine | D6: Azacitidine | E6: INJECTION, POWDER, LYOPHILIZED, FOR SOLUTION | F6: NDA | G6: NDA208216 | H6: BluePoint Laboratories | I6: AZACITIDINE | J6: 100 | K6: mg/1 | L6: 20170701
A7: Azacitidine Injection | B7: 68001-620 | C7: Azacitidine | D7: Azacitidine | E7: INJECTION, POWDER, LYOPHILIZED, FOR SOLUTION | F7: ANDA | G7: ANDA201537 | H7: BluePoint Laboratories. | I7: AZACITIDINE | J7: 100 | K7: mg/1 | L7: 20250110
A8: Azacitidine Injection | B8: 31722-365 | C8: Azacitidine | D8: Azacitidine | E8: INJECTION, POWDER, LYOPHILIZED, FOR SOLUTION | F8: ANDA | G8: ANDA215765 | H8: Camber Pharmaceuticals, Inc. | I8: AZACITIDINE | J8: 100 | K8: mg/1 | L8: 20241015
A9: Azacitidine Injection | B9: 59572-102 | C9: VIDAZA | D9: azacitidine | E9: INJECTION, POWDER, LYOPHILIZED, FOR SOLUTION | F9: NDA | G9: NDA050794 | H9: Celgene Corporation | I9: AZACITIDINE | J9: 100 | K9: mg/1 | L9: 20040705
A10: Azacitidine Injection | B10: 72572-020 | C10: Azacitidine | D10: Azacitidine | E10: INJECTION, POWDER, LYOPHILIZED, FOR SOLUTION | F10: ANDA | G10: ANDA212580 | H10: Civica, Inc. | I10: AZACITIDINE | J10: 100 | K10: mg/1 | L10: 20240516
A11: Azacitidine Injection | B11: 43598-305 | C11: Azacitidine | D11: Azacitidine | E11: INJECTION, POWDER, LYOPHILIZED, FOR SOLUTION | F11: ANDA | G11: ANDA201537 | H11: Dr. Reddy's Laboratories Inc. | I11: AZACITIDINE | J11: 100 | K11: mg/1 | L11: 20130919
A12: Azacitidine Injection | B12: 43598-465 | C12: Azacitidine | D12: Azacitidine | E12: INJECTION, POWDER, LYOPHILIZED, FOR SOLUTION | F12: ANDA | G12: ANDA201537 | H12: Dr. Reddy's Laboratories Inc. | I12: AZACITIDINE | J12: 100 | K12: mg/1 | L12: 20150619
... A74: Dexamethasone Sodium Phosphate Injection | B74: 80425-0261 | C74: Dexamethasone Sodium Phosphate | D74: Dexamethasone Sodium Phosphate | E74: INJECTION | F74: ANDA | G74: ANDA207442 | H74: Advanced Rx Pharmacy of Tennessee, LLC | I74: DEXAMETHASONE SODIUM PHOSPHATE | J74: 10 | K74: mg/mL | L74: 20230216
A75: Dexamethasone Sodium Phosphate Injection | B75: 80425-0556 | C75: DMT SUIK | D75: Dexamethasone Sodium Phosphate | E75: INJECTION, SOLUTION | F75: UNAPPROVED DRUG OTHER | H75: Advanced Rx of Tennessee, LLC | I75: DEXAMETHASONE SODIUM PHOSPHATE | J75: 10 | K75: mg/mL | L75: 20251107
A76: Dexamethasone Sodium Phosphate Injection | B76: 70121-1399 | C76: Dexamethasone Sodium Phosphate | D76: Dexamethasone Sodium Phosphate | E76: INJECTION, SOLUTION | F76: ANDA | G76: ANDA208690 | H76: Amneal Pharmaceuticals LLC | I76: DEXAMETHASONE SODIUM PHOSPHATE | J76: 10 | K76: mg/mL | L76: 20180826
A77: Dexamethasone Sodium Phosphate Injection | B77: 70121-1450 | C77: Dexamethasone Sodium Phosphate | D77: Dexamethasone Sodium Phosphate | E77: INJECTION, SOLUTION | F77: ANDA | G77: ANDA208689 | H77: Amneal Pharmaceuticals LLC | I77: DEXAMETHASONE SODIUM PHOSPHATE | J77: 4 | K77: mg/mL | L77: 20180827
A78: Dexamethasone Sodium Phosphate Injection | B78: 70121-1451 | C78: Dexamethasone Sodium Phosphate | D78: Dexamethasone Sodium Phosphate | E78: INJECTION, SOLUTION | F78: ANDA | G78: ANDA208689 | H78: Amneal Pharmaceuticals LLC | I78: DEXAMETHASONE SODIUM PHOSPHATE | J78: 4 | K78: mg/mL | L78: 20180827
A79: Dexamethasone Sodium Phosphate Injection | B79: 70121-1452 | C79: Dexamethasone Sodium Phosphate | D79: Dexamethasone Sodium Phosphate | E79: INJECTION, SOLUTION | F79: ANDA | G79: ANDA208689 | H79: Amneal Pharmaceuticals LLC | I79: DEXAMETHASONE SODIUM PHOSPHATE | J79: 4 | K79: mg/mL | L79: 20180827
A80: Dexamethasone Sodium Phosphate Injection | B80: 72485-118 | C80: Dexamethasone Sodium Phosphate | D80: Dexamethasone Sodium Phosphate | E80: INJECTION, SOLUTION | F80: ANDA | G80: ANDA217797 | H80: Armas Pharmaceuticals | I80: DEXAMETHASONE SODIUM PHOSPHATE | J80: 10 | K80: mg/mL | L80: 20250422
A81: Dexamethasone Sodium Phosphate Injection | B81: 76420-077 | C81: DEXAMETHASONE SODIUM PHOSPHATE | D81: DEXAMETHASONE SODIUM PHOSPHATE | E81: INJECTION, SOLUTION | F81: ANDA | G81: ANDA206781 | H81: Asclemed USA, Inc. | I81: DEXAMETHASONE SODIUM PHOSPHATE | J81: 4 | K81: mg/mL | L81: 20200211
A82: Dexamethasone Sodium Phosphate Injection | B82: 76420-185 | C82: Dexamethasone Sodium Phosphate | D82: Dexamethasone Sodium Phosphate | E82: INJECTION, SOLUTION | F82: ANDA | G82: ANDA040803 | H82: Asclemed USA, Inc. | I82: DEXAMETHASONE SODIUM PHOSPHATE | J82: 4 | K82: mg/mL | L82: 20110511
A83: Dexamethasone Sodium Phosphate Injection | B83: 76420-270 | C83: DMT SUIK | D83: Dexamethasone Sodium Phosphate | E83: INJECTION, SOLUTION | F83: UNAPPROVED DRUG OTHER | H83: Asclemed USA, Inc. | I83: DEXAMETHASONE SODIUM PHOSPHATE | J83: 10 | K83: mg/mL | L83: 20030529
A84: Dexamethasone Sodium Phosphate Injection | B84: 76420-396 | C84: Dexamethasone Sodium Phosphate | D84: Dexamethasone Sodium Phosphate | E84: INJECTION, SOLUTION | F84: ANDA | G84: ANDA040803 | H84: Asclemed USA, Inc. | I84: DEXAMETHASONE SODIUM PHOSPHATE | J84: 4 | K84: mg/mL | L84: 20110511
A85: Dexamethasone Sodium Phosphate Injection | B85: 76420-397 | C85: Dexamethasone Sodium Phosphate | D85: Dexamethasone Sodium Phosphate | E85: INJECTION, SOLUTION | F85: ANDA | G85: ANDA040803 | H85: Asclemed USA, Inc. | I85: DEXAMETHASONE SODIUM PHOSPHATE | J85: 4 | K85: mg/mL | L85: 20110511
A86: Dexamethasone Sodium Phosphate Injection | B86: 76420-398 | C86: Dexamethasone Sodium Phosphate | D86: Dexamethasone Sodium Phosphate | E86: INJECTION, SOLUTION | F86: ANDA | G86: ANDA040803 | H86: Asclemed USA, Inc. | I86: DEXAMETHASONE SODIUM PHOSPHATE | J86: 4 | K86: mg/mL | L86: 20110511
A87: Dexamethasone Sodium Phosphate Injection | B87: 76420-399 | C87: Dexamethasone Sodium Phosphate | D87: Dexamethasone Sodium Phosphate | E87: INJECTION, SOLUTION | F87: ANDA | G87: ANDA040802 | H87: Asclemed USA, Inc. | I87: DEXAMETHASONE SODIUM PHOSPHATE | J87: 10 | K87: mg/mL | L87: 20110511
A88: Dexamethasone Sodium Phosphate Injection | B88: 76420-555 | C88: Dexamethasone Sodium Phosphate | D88: Dexamethasone Sodium Phosphate | E88: INJECTION | F88: ANDA | G88: ANDA084282 | H88: Asclemed USA, Inc. | I88: DEXAMETHASONE SODIUM PHOSPHATE | J88: 4 | K88: mg/mL | L88: 19750715
A89: Dexamethasone Sodium Phosphate Injection | B89: 55154-5118 | C89: Dexamethasone Sodium Phosphate | D89: Dexamethasone Sodium Phosphate | E89: INJECTION | F89: ANDA | G89: ANDA087702 | H89: Cardinal Health 107, LLC | I89: DEXAMETHASONE SODIUM PHOSPHATE | J89: 10 | K89: mg/mL | L89: 19820907
A90: Dexamethasone Sodium Phosphate Injection | B90: 55154-9364 | C90: Dexamethasone Sodium Phosphate | D90: DEXAMETHASONE SODIUM PHOSPHATE | E90: INJECTION, SOLUTION | F90: ANDA | G90: ANDA084916 | H90: Cardinal Health 107, LLC | I90: DEXAMETHASONE SODIUM PHOSPHATE | J90: 4 | K90: mg/mL | L90: 20000907
A91: Dexamethasone Sodium Phosphate Injection | B91: 72572-120 | C91: Dexamethasone Sodium Phosphate | D91: Dexamethasone Sodium Phosphate | E91: INJECTION | F91: ANDA | G91: ANDA084282 | H91: Civica, Inc. | I91: DEXAMETHASONE SODIUM PHOSPHATE | J91: 4 | K91: mg/mL | L91: 20191113
A92: Dexamethasone Sodium Phosphate Injection | B92: 72572-122 | C92: Dexamethasone Sodium Phosphate | D92: Dexamethasone Sodium Phosphate | E92: INJECTION | F92: ANDA | G92: ANDA087702 | H92: Civica, Inc. | I92: DEXAMETHASONE SODIUM PHOSPHATE | J92: 10 | K92: mg/mL | L92: 20191113
A93: Dexamethasone Sodium Phosphate Injection | B93: 55150-237 | C93: DEXAMETHASONE SODIUM PHOSPHATE | D93: DEXAMETHASONE SODIUM PHOSPHATE | E93: INJECTION, SOLUTION | F93: ANDA | G93: ANDA206781 | H93: Eugia US LLC | I93: DEXAMETHASONE SODIUM PHOSPHATE | J93: 4 | K93: mg/mL | L93: 20151201
A94: Dexamethasone Sodium Phosphate Injection | B94: 55150-238 | C94: DEXAMETHASONE SODIUM PHOSPHATE | D94: DEXAMETHASONE SODIUM PHOSPHATE | E94: INJECTION, SOLUTION | F94: ANDA | G94: ANDA206781 | H94: Eugia US LLC | I94: DEXAMETHASONE SODIUM PHOSPHATE | J94: 4 | K94: mg/mL | L94: 20151201
A95: Dexamethasone Sodium Phosphate Injection | B95: 55150-239 | C95: DEXAMETHASONE SODIUM PHOSPHATE | D95: DEXAMETHASONE SODIUM PHOSPHATE | E95: INJECTION, SOLUTION | F95: ANDA | G95: ANDA206781 | H95: Eugia US LLC | I95: DEXAMETHASONE SODIUM PHOSPHATE | J95: 4 | K95: mg/mL | L95: 20151201
... A176: Ifosfamide Injection | B176: 71288-181 | C176: Ifosfamide | D176: Ifosfamide | E176: INJECTION, SOLUTION | F176: ANDA | G176: ANDA076657 | H176: Meitheal Pharmaceutical Inc. | I176: IFOSFAMIDE | J176: 3 | K176: g/60mL | L176: 20070726
A177: Ifosfamide Injection | B177: 21586-211 | C177: Ifosfamide | D177: Ifosfamide for Injection | E177: POWDER, FOR SOLUTION | F177: UNAPPROVED DRUG FOR USE IN DRUG SHORTAGE | H177: SteriMax Inc. | I177: IFOSFAMIDE | J177: 1 | K177: g/1 | L177: 20260904
A178: Methotrexate Sodium Injection | B178: 16729-277 | C178: Methotrexate | D178: Methotrexate | E178: INJECTION | F178: ANDA | G178: ANDA040716 | H178: Accord Healthcare, Inc. | I178: METHOTREXATE | J178: 25 | K178: mg/mL | L178: 20140307
A179: Methotrexate Sodium Injection | B179: 62332-711 | C179: METHOTREXATE | D179: methotrexate | E179: INJECTION, SOLUTION | F179: ANDA | G179: ANDA220225 | H179: Alembic Pharmaceuticals Inc. | I179: METHOTREXATE SODIUM | J179: 25 | K179: mg/mL | L179: 20260415
A180: Methotrexate Sodium Injection | B180: 62332-712 | C180: METHOTREXATE | D180: methotrexate | E180: INJECTION, SOLUTION | F180: ANDA | G180: ANDA220225 | H180: Alembic Pharmaceuticals Inc. | I180: METHOTREXATE SODIUM | J180: 25 | K180: mg/mL | L180: 20260415
A181: Methotrexate Sodium Injection | B181: 46708-711 | C181: METHOTREXATE | D181: methotrexate | E181: INJECTION, SOLUTION | F181: ANDA | G181: ANDA220225 | H181: Alembic Pharmaceuticals Limited | I181: METHOTREXATE SODIUM | J181: 25 | K181: mg/mL | L181: 20260415
...

Sheet Inputs
A1: Model inputs
A3: Measure | B3: Patient risk | C3: Market entry
A4: Severity: share of products unavailable | B4: 0.5 | C4: 0.2
A5: Persistence: years in shortage | B5: 0.25 | C5: 0.4
A6: Few generic competitors (ANDA approvals) | B6: 0.25 | C6: 0.4
A7: Total | B7: =SUM(B4:B6) -> 1 | C7: =SUM(C4:C6) -> 1
A9: Selected view | B9: Patient risk

Sheet Model
A1: Drug | B1: Severity | C1: Persistence | D1: Few competitors | E1: Patient risk score | F1: Market entry score | G1: Selected score | H1: Rank
A2: {=_xlfn._xlws.FILTER(Data!A2:A9,Data!L2:L9="Yes")} -> Azacitidine Injection | B2: =(_xlfn.XLOOKUP(A2,Data!$A$2:$A$9,Data!$D$2:$D$9)-_xlfn.MINIFS(Data!$D$2:$D$9,Data!$L$2:$L$9,"Yes"))/(_xlfn.MAXIFS(Data!$D$2:$D$9,Data!$L$2:$L$9,"Yes")-_xlfn.MINIFS(Data!$D$2:$D$9,Data!$L$2:$L$9,"Yes")) -> 0.2962963 | C2: =(_xlfn.XLOOKUP(A2,Data!$A$2:$A$9,Data!$G$2:$G$9)-_xlfn.MINIFS(Data!$G$2:$G$9,Data!$L$2:$L$9,"Yes"))/(_xlfn.MAXIFS(Data!$G$2:$G$9,Data!$L$2:$L$9,"Yes")-_xlfn.MINIFS(Data!$G$2:$G$9,Data!$L$2:$L$9,"Yes")) -> 0.75364238 | D2: =1-(_xlfn.XLOOKUP(A2,Data!$A$2:$A$9,Data!$J$2:$J$9)-_xlfn.MINIFS(Data!$J$2:$J$9,Data!$L$2:$L$9,"Yes"))/(_xlfn.MAXIFS(Data!$J$2:$J$9,Data!$L$2:$L$9,"Yes")-_xlfn.MINIFS(Data!$J$2:$J$9,Data!$L$2:$L$9,"Yes")) -> 0.36842105 | E2: =B2*Inputs!$B$4+C2*Inputs!$B$5+D2*Inputs!$B$6 -> 0.42866401 | F2: =B2*Inputs!$C$4+C2*Inputs!$C$5+D2*Inputs!$C$6 -> 0.50808463 | G2: =IF(Inputs!$B$9="Patient risk",E2,F2) -> 0.42866401 | H2: =_xlfn.RANK.EQ(G2,$G$2:$G$8) -> 3
A3: Carboplatin Injection | B3: =(_xlfn.XLOOKUP(A3,Data!$A$2:$A$9,Data!$D$2:$D$9)-_xlfn.MINIFS(Data!$D$2:$D$9,Data!$L$2:$L$9,"Yes"))/(_xlfn.MAXIFS(Data!$D$2:$D$9,Data!$L$2:$L$9,"Yes")-_xlfn.MINIFS(Data!$D$2:$D$9,Data!$L$2:$L$9,"Yes")) -> 0.25747126 | C3: =(_xlfn.XLOOKUP(A3,Data!$A$2:$A$9,Data!$G$2:$G$9)-_xlfn.MINIFS(Data!$G$2:$G$9,Data!$L$2:$L$9,"Yes"))/(_xlfn.MAXIFS(Data!$G$2:$G$9,Data!$L$2:$L$9,"Yes")-_xlfn.MINIFS(Data!$G$2:$G$9,Data!$L$2:$L$9,"Yes")) -> 0.4410596 | D3: =1-(_xlfn.XLOOKUP(A3,Data!$A$2:$A$9,Data!$J$2:$J$9)-_xlfn.MINIFS(Data!$J$2:$J$9,Data!$L$2:$L$9,"Yes"))/(_xlfn.MAXIFS(Data!$J$2:$J$9,Data!$L$2:$L$9,"Yes")-_xlfn.MINIFS(Data!$J$2:$J$9,Data!$L$2:$L$9,"Yes")) -> 0.57894737 | E3: =B3*Inputs!$B$4+C3*Inputs!$B$5+D3*Inputs!$B$6 -> 0.38373737 | F3: =B3*Inputs!$C$4+C3*Inputs!$C$5+D3*Inputs!$C$6 -> 0.45949704 | G3: =IF(Inputs!$B$9="Patient risk",E3,F3) -> 0.38373737 | H3: =_xlfn.RANK.EQ(G3,$G$2:$G$8) -> 4
A4: Dexamethasone Sodium Phosphate Injection | B4: =(_xlfn.XLOOKUP(A4,Data!$A$2:$A$9,Data!$D$2:$D$9)-_xlfn.MINIFS(Data!$D$2:$D$9,Data!$L$2:$L$9,"Yes"))/(_xlfn.MAXIFS(Data!$D$2:$D$9,Data!$L$2:$L$9,"Yes")-_xlfn.MINIFS(Data!$D$2:$D$9,Data!$L$2:$L$9,"Yes")) -> 0 | C4: =(_xlfn.XLOOKUP(A4,Data!$A$2:$A$9,Data!$G$2:$G$9)-_xlfn.MINIFS(Data!$G$2:$G$9,Data!$L$2:$L$9,"Yes"))/(_xlfn.MAXIFS(Data!$G$2:$G$9,Data!$L$2:$L$9,"Yes")-_xlfn.MINIFS(Data!$G$2:$G$9,Data!$L$2:$L$9,"Yes")) -> 1 | D4: =1-(_xlfn.XLOOKUP(A4,Data!$A$2:$A$9,Data!$J$2:$J$9)-_xlfn.MINIFS(Data!$J$2:$J$9,Data!$L$2:$L$9,"Yes"))/(_xlfn.MAXIFS(Data!$J$2:$J$9,Data!$L$2:$L$9,"Yes")-_xlfn.MINIFS(Data!$J$2:$J$9,Data!$L$2:$L$9,"Yes")) -> 0 | E4: =B4*Inputs!$B$4+C4*Inputs!$B$5+D4*Inputs!$B$6 -> 0.25 | F4: =B4*Inputs!$C$4+C4*Inputs!$C$5+D4*Inputs!$C$6 -> 0.4 | G4: =IF(Inputs!$B$9="Patient risk",E4,F4) -> 0.25 | H4: =_xlfn.RANK.EQ(G4,$G$2:$G$8) -> 7
A5: Ifosfamide Injection | B5: =(_xlfn.XLOOKUP(A5,Data!$A$2:$A$9,Data!$D$2:$D$9)-_xlfn.MINIFS(Data!$D$2:$D$9,Data!$L$2:$L$9,"Yes"))/(_xlfn.MAXIFS(Data!$D$2:$D$9,Data!$L$2:$L$9,"Yes")-_xlfn.MINIFS(Data!$D$2:$D$9,Data!$L$2:$L$9,"Yes")) -> 0.20833333 | C5: =(_xlfn.XLOOKUP(A5,Data!$A$2:$A$9,Data!$G$2:$G$9)-_xlfn.MINIFS(Data!$G$2:$G$9,Data!$L$2:$L$9,"Yes"))/(_xlfn.MAXIFS(Data!$G$2:$G$9,Data!$L$2:$L$9,"Yes")-_xlfn.MINIFS(Data!$G$2:$G$9,Data!$L$2:$L$9,"Yes")) -> 0.02781457 | D5: =1-(_xlfn.XLOOKUP(A5,Data!$A$2:$A$9,Data!$J$2:$J$9)-_xlfn.MINIFS(Data!$J$2:$J$9,Data!$L$2:$L$9,"Yes"))/(_xlfn.MAXIFS(Data!$J$2:$J$9,Data!$L$2:$L$9,"Yes")-_xlfn.MINIFS(Data!$J$2:$J$9,Data!$L$2:$L$9,"Yes")) -> 0.84210526 | E5: =B5*Inputs!$B$4+C5*Inputs!$B$5+D5*Inputs!$B$6 -> 0.32164662 | F5: =B5*Inputs!$C$4+C5*Inputs!$C$5+D5*Inputs!$C$6 -> 0.3896346 | G5: =IF(Inputs!$B$9="Patient risk",E5,F5) -> 0.32164662 | H5: =_xlfn.RANK.EQ(G5,$G$2:$G$8) -> 5
A6: Methotrexate Sodium Injection | B6: =(_xlfn.XLOOKUP(A6,Data!$A$2:$A$9,Data!$D$2:$D$9)-_xlfn.MINIFS(Data!$D$2:$D$9,Data!$L$2:$L$9,"Yes"))/(_xlfn.MAXIFS(Data!$D$2:$D$9,Data!$L$2:$L$9,"Yes")-_xlfn.MINIFS(Data!$D$2:$D$9,Data!$L$2:$L$9,"Yes")) -> 0.095238095 | C6: =(_xlfn.XLOOKUP(A6,Data!$A$2:$A$9,Data!$G$2:$G$9)-_xlfn.MINIFS(Data!$G$2:$G$9,Data!$L$2:$L$9,"Yes"))/(_xlfn.MAXIFS(Data!$G$2:$G$9,Data!$L$2:$L$9,"Yes")-_xlfn.MINIFS(Data!$G$2:$G$9,Data!$L$2:$L$9,"Yes")) -> 0.45827815 | D6: =1-(_xlfn.XLOOKUP(A6,Data!$A$2:$A$9,Data!$J$2:$J$9)-_xlfn.MINIFS(Data!$J$2:$J$9,Data!$L$2:$L$9,"Yes"))/(_xlfn.MAXIFS(Data!$J$2:$J$9,Data!$L$2:$L$9,"Yes")-_xlfn.MINIFS(Data!$J$2:$J$9,Data!$L$2:$L$9,"Yes")) -> 0.63157895 | E6: =B6*Inputs!$B$4+C6*Inputs!$B$5+D6*Inputs!$B$6 -> 0.32008332 | F6: =B6*Inputs!$C$4+C6*Inputs!$C$5+D6*Inputs!$C$6 -> 0.45499046 | G6: =IF(Inputs!$B$9="Patient risk",E6,F6) -> 0.32008332 | H6: =_xlfn.RANK.EQ(G6,$G$2:$G$8) -> 6
A7: Pentostatin Injection | B7: =(_xlfn.XLOOKUP(A7,Data!$A$2:$A$9,Data!$D$2:$D$9)-_xlfn.MINIFS(Data!$D$2:$D$9,Data!$L$2:$L$9,"Yes"))/(_xlfn.MAXIFS(Data!$D$2:$D$9,Data!$L$2:$L$9,"Yes")-_xlfn.MINIFS(Data!$D$2:$D$9,Data!$L$2:$L$9,"Yes")) -> 1 | C7: =(_xlfn.XLOOKUP(A7,Data!$A$2:$A$9,Data!$G$2:$G$9)-_xlfn.MINIFS(Data!$G$2:$G$9,Data!$L$2:$L$9,"Yes"))/(_xlfn.MAXIFS(Data!$G$2:$G$9,Data!$L$2:$L$9,"Yes")-_xlfn.MINIFS(Data!$G$2:$G$9,Data!$L$2:$L$9,"Yes")) -> 0 | D7: =1-(_xlfn.XLOOKUP(A7,Data!$A$2:$A$9,Data!$J$2:$J$9)-_xlfn.MINIFS(Data!$J$2:$J$9,Data!$L$2:$L$9,"Yes"))/(_xlfn.MAXIFS(Data!$J$2:$J$9,Data!$L$2:$L$9,"Yes")-_xlfn.MINIFS(Data!$J$2:$J$9,Data!$L$2:$L$9,"Yes")) -> 1 | E7: =B7*Inputs!$B$4+C7*Inputs!$B$5+D7*Inputs!$B$6 -> 0.75 | F7: =B7*Inputs!$C$4+C7*Inputs!$C$5+D7*Inputs!$C$6 -> 0.6 | G7: =IF(Inputs!$B$9="Patient risk",E7,F7) -> 0.75 | H7: =_xlfn.RANK.EQ(G7,$G$2:$G$8) -> 1
A8: Streptozocin Powder, For Solution | B8: =(_xlfn.XLOOKUP(A8,Data!$A$2:$A$9,Data!$D$2:$D$9)-_xlfn.MINIFS(Data!$D$2:$D$9,Data!$L$2:$L$9,"Yes"))/(_xlfn.MAXIFS(Data!$D$2:$D$9,Data!$L$2:$L$9,"Yes")-_xlfn.MINIFS(Data!$D$2:$D$9,Data!$L$2:$L$9,"Yes")) -> 0.36666667 | C8: =(_xlfn.XLOOKUP(A8,Data!$A$2:$A$9,Data!$G$2:$G$9)-_xlfn.MINIFS(Data!$G$2:$G$9,Data!$L$2:$L$9,"Yes"))/(_xlfn.MAXIFS(Data!$G$2:$G$9,Data!$L$2:$L$9,"Yes")-_xlfn.MINIFS(Data!$G$2:$G$9,Data!$L$2:$L$9,"Yes")) -> 0.54701987 | D8: =1-(_xlfn.XLOOKUP(A8,Data!$A$2:$A$9,Data!$J$2:$J$9)-_xlfn.MINIFS(Data!$J$2:$J$9,Data!$L$2:$L$9,"Yes"))/(_xlfn.MAXIFS(Data!$J$2:$J$9,Data!$L$2:$L$9,"Yes")-_xlfn.MINIFS(Data!$J$2:$J$9,Data!$L$2:$L$9,"Yes")) -> 1 | E8: =B8*Inputs!$B$4+C8*Inputs!$B$5+D8*Inputs!$B$6 -> 0.5700883 | F8: =B8*Inputs!$C$4+C8*Inputs!$C$5+D8*Inputs!$C$6 -> 0.69214128 | G8: =IF(Inputs!$B$9="Patient risk",E8,F8) -> 0.5700883 | H8: =_xlfn.RANK.EQ(G8,$G$2:$G$8) -> 2

Sheet Output
A1: ="Ranking: "&Inputs!B9 -> Ranking: Patient risk
A3: Rank | B3: Drug | C3: Score
A4: {=_xlfn.SEQUENCE(7)} -> 1 | B4: {=_xlfn.SORTBY(Model!A2:A8,Model!G2:G8,-1)} -> Pentostatin Injection | C4: {=_xlfn.SORTBY(Model!G2:G8,Model!G2:G8,-1)} -> 0.75
A5: 2 | B5: Streptozocin Powder, For Solution | C5: 0.5700883
A6: 3 | B6: Azacitidine Injection | C6: 0.42866401
A7: 4 | B7: Carboplatin Injection | C7: 0.38373737
A8: 5 | B8: Ifosfamide Injection | C8: 0.32164662
A9: 6 | B9: Methotrexate Sodium Injection | C9: 0.32008332
A10: 7 | B10: Dexamethasone Sodium Phosphate Injection | C10: 0.25
